Workbook

Sheet 대시보드
A3: 전체 프로젝트 진행률 | D3: =COUNTIF('마일스톤'!K:K,"완료")/COUNTA('마일스톤'!A3:A97) -> 0
A4: 완료된 작업 수 | D4: =COUNTIF('마일스톤'!K:K,"완료")&" / "&COUNTA('마일스톤'!A3:A97) -> 0 / 49
A5: 진행중인 작업 수 | D5: =COUNTIF('마일스톤'!K:K,"진행중") -> 0
A6: 대기중인 작업 수 | D6: =COUNTIF('마일스톤'!K:K,"대기") -> 49
A9: 🎯 마일스톤 현황
A10: 마일스톤 | B10: 설명 | C10: 예정일 | D10: 진행률(%) | E10: 상태
A11: M1 | B11: 기획 및 준비 완료 | C11: 45973 | D11: ='마일스톤'!J3 -> 0 | E11: =IF(D11=100,"✅ 완료",IF(D11>0,"🔄 진행중","⏸️ 대기")) -> ⏸️ 대기
A12: M2 | B12: 데이터 수집 및 전처리 완료 | C12: 45979 | D12: ='마일스톤'!J14 -> 0 | E12: =IF(D12=100,"✅ 완료",IF(D12>0,"🔄 진행중","⏸️ 대기")) -> ⏸️ 대기
A13: M3 | B13: 데이터 분석 및 시각화 완료 | C13: 45985 | D13: ='마일스톤'!J30 -> 0 | E13: =IF(D13=100,"✅ 완료",IF(D13>0,"🔄 진행중","⏸️ 대기")) -> ⏸️ 대기
A14: M4 | B14: 발표자료 및 최종보고서 완료 | C14: 45987 | D14: ='마일스톤'!J45 -> 0 | E14: =IF(D14=100,"✅ 완료",IF(D14>0,"🔄 진행중","⏸️ 대기")) -> ⏸️ 대기
A15: M5 | B15: 최종 발표 | C15: 45988 | D15: ='마일스톤'!J51 | E15: =IF(D15=100,"✅ 완료",IF(D15>0,"🔄 진행중","⏸️ 대기")) -> ⏸️ 대기
A18: 💼 일일 업무 보고 | E18: =today() -> 45996
A19: 구분 | B19: 담당업무(메인/서브) | C19: 퇴근시간 | D19: 특이사항 | E19: 개인 업무 보고 시트
A20: 김효정 | B20: AA/DA | C20: 0.75 | E20: 김효정개인보고시트
A21: 김한준 | B21: DA/AA | C21: 0.75 | E21: 김한준개인보고시트
A22: 이상윤 | B22: DA/TA | C22: 0.75 | E22: 이상윤개인보고시트
A23: 정우식 | B23: TA/DA | C23: 0.75 | E23: 정우식개인보고시트

Sheet 마일스톤
L1: November
A2: WBS | B2: 작업명 | C2: 담당자 | D2: 예상시작일 | E2: 예상종료일 | F2: 예상기간(일) | G2: 실제시작일 | H2: 실제종료일 | I2: 실제기간(일) | J2: 진행률(%) | K2: 상태 | L2: Week1 | S2: Week2 | Z2: Week3 | AG2: Week4
A3: 1 | B3: 기획 및 준비 | D3: 45964 | E3: 45973 | F3: =E3-D3+1 -> 10 | I3: =H3-G3+1 -> 1 | J3: =sum(J4:J13)/COUNT(F4:F13) -> 0 | K3: 대기 | L3: =J3 -> 0 | V3: 기획 및 준비(11/3-11/12)
A4: 1.1 | B4: 프로젝트 킥오프 | D4: 45964 | E4: 45973 | F4: =E4-D4+1 -> 10 | I4: =H4-G4+1 -> 1 | J4: =sum(J5:J8)/COUNT(F5:F8) -> 0 | K4: 대기 | L4: =J4 -> 0 | V4: 프로젝트 킥오프(11/3-11/12)
A5: 1.1.1 | B5: 기획 및 주제 선정 | C5: 전체 | D5: 45964 | E5: 45971 | F5: =E5-D5+1 -> 8 | I5: =H5-G5+1 -> 1 | K5: 대기 | L5: =J5 | V5: 기획 및 주제 선정(11/3-11/10)
A6: 1.1.2 | B6: 분석 배경 기술 | C6: AA | D6: 45972 | E6: 45973 | F6: =E6-D6+1 -> 2 | I6: =H6-G6+1 -> 1 | K6: 대기 | T6: =J6 | V6: 분석 배경 기술(11/11-11/12)
A7: 1.1.3 | B7: 분석 절차 정립 | C7: AA | D7: 45972 | E7: 45973 | F7: =E7-D7+1 -> 2 | I7: =H7-G7+1 -> 1 | K7: 대기 | T7: =J7 | V7: 분석 절차 정립(11/11-11/12)
A8: 1.1.4 | B8: 분석 목표 및 범위 설정 | C8: AA | D8: 45972 | E8: 45973 | F8: =E8-D8+1 -> 2 | I8: =H8-G8+1 -> 1 | K8: 대기 | T8: =J8 | V8: 분석 목표 및 범위 설정(11/11-11/12)
A9: 1.2 | B9: 문제 정의 | D9: 45972 | E9: 45973 | F9: =E9-D9+1 -> 2 | I9: =H9-G9+1 -> 1 | J9: =sum(J10:J13)/COUNT(F10:F13) -> 0 | K9: 대기 | T9: =J9 -> 0 | V9: 문제 정의(11/11-11/12)
A10: 1.2.1 | B10: 선행연구 및 방법론 탐색 | C10: DA, TA | D10: 45972 | E10: 45973 | F10: =E10-D10+1 -> 2 | I10: =H10-G10+1 -> 1 | K10: 대기 | T10: =J10 | V10: 선행연구 및 방법론 탐색(11/11-11/12)
A11: 1.2.2 | B11: 문제 정의 및 분석방법 선정 | C11: DA | D11: 45972 | E11: 45973 | F11: =E11-D11+1 -> 2 | I11: =H11-G11+1 -> 1 | K11: 대기 | T11: =J11 | V11: 문제 정의 및 분석방법 선정(11/11-11/12)
A12: 1.2.3 | B12: 데이터 수집 채널 선정 | C12: DA | D12: 45972 | E12: 45973 | F12: =E12-D12+1 -> 2 | I12: =H12-G12+1 -> 1 | K12: 대기 | T12: =J12 | V12: 데이터 수집 채널 선정(11/11-11/12)
A13: 1.2.4 | B13: 데이터 수집 리스트업 | C13: AA | D13: 45972 | E13: 45973 | F13: =E13-D13+1 -> 2 | I13: =H13-G13+1 -> 1 | K13: 대기 | T13: =J13 | V13: 데이터 수집 리스트업(11/11-11/12)
A14: 2 | B14: 데이터 수집 및 전처리 | D14: 45973 | E14: 45979 | F14: =E14-D14+1 -> 7 | I14: =H14-G14+1 -> 1 | J14: =sum(J15:J29)/COUNT(F15:F29) -> 0 | K14: 대기 | U14: =J14 -> 0 | AB14: 데이터 수집 및 전처리(11/12-11/18)
A15: 2.1 | B15: 데이터 수집 | D15: 45973 | E15: 45975 | F15: =E15-D15+1 -> 3 | I15: =H15-G15+1 -> 1 | K15: 대기 | U15: =J15 | X15: 데이터 수집(11/12-11/13)
A16: 2.1.1 | B16: raw data 수집 | C16: DA, TA | D16: 45973 | E16: 45974 | F16: =E16-D16+1 -> 2 | I16: =H16-G16+1 -> 1 | K16: 대기 | U16: =J16 | W16: raw data 수집(11/12-11/13)
A17: 2.1.2 | B17: 데이터 검토 및 정리 | C17: AA, DA | D17: 45973 | E17: 45974 | F17: =E17-D17+1 -> 2 | I17: =H17-G17+1 -> 1 | K17: 대기 | U17: =J17 | W17: 데이터 검토 및 정리(11/12-11/13)
A18: 2.1.3 | B18: 추가 데이터 수집 | C18: DA, TA | D18: 45975 | E18: 45975 | F18: =E18-D18+1 -> 1 | I18: =H18-G18+1 -> 1 | K18: 대기 | W18: =J18 | X18: 추가 데이터 수집(11/14-11/14)
A19: 2.1.4 | B19: 수집 현황표 작성 및 공유 | C19: AA | D19: 45975 | E19: 45975 | F19: =E19-D19+1 -> 1 | I19: =H19-G19+1 -> 1 | K19: 대기 | W19: =J19 | X19: 수집 현황표 작성 및 공유(11/14-11/14)
A20: 2.2 | B20: 데이터 이해 및 통합화 | D20: 45978 | E20: 45979 | F20: =E20-D20+1 -> 2 | I20: =H20-G20+1 -> 1 | K20: 대기 | Z20: =J20 | AB20: 데이터 이해 및 통합화(11/17-11/18)
A21: 2.2.1 | B21: 데이터 형태 및 주요 컬럼 확인(변수설정) | C21: DA | D21: 45978 | E21: 45978 | F21: =E21-D21+1 -> 1 | I21: =H21-G21+1 -> 1 | K21: 대기 | Z21: =J21 | AA21: 데이터 형태 및 주요 컬럼 확인(변수설정)(11/17-11/17)
A22: 2.2.2 | B22: 컬럼명 표준화 및 맵핑 | C22: DA | D22: 45978 | E22: 45978 | F22: =E22-D22+1 -> 1 | I22: =H22-G22+1 -> 1 | K22: 대기 | Z22: =J22 | AA22: 컬럼명 표준화 및 맵핑(11/17-11/17)
A23: 2.2.3 | B23: 데이터 연결 구조 검토(테이블 관계 설정) | C23: DA | D23: 45978 | E23: 45978 | F23: =E23-D23+1 -> 1 | I23: =H23-G23+1 -> 1 | K23: 대기 | Z23: =J25 | AB23: 데이터 연결 구조 검토(테이블 관계 설정)(11/17-11/17)
A24: 2.2.4 | B24: 데이터명세서 작성 | C24: AA | D24: 45978 | E24: 45979 | F24: =E24-D24+1 -> 2 | I24: =H24-G24+1 -> 1 | K24: 대기 | Z24: =J24 | AB24: 데이터명세서 작성(11/17-11/18)
A25: 2.3 | B25: 데이터 정제 | D25: 45978 | E25: 45979 | F25: =E25-D25+1 -> 2 | I25: =H25-G25+1 -> 1 | K25: 대기 | Z25: =J25 | AB25: 데이터 정제(11/17-11/18)
A26: 2.3.1 | B26: 결측값 및 이상치 처리 | C26: DA | D26: 45978 | E26: 45979 | F26: =E26-D26+1 -> 2 | I26: =H26-G26+1 -> 1 | K26: 대기 | Z26: =J26 | AB26: 결측값 및 이상치 처리(11/17-11/18)
A27: 2.3.2 | B27: 데이터 타입 변환 및 포맷 통일 | C27: DA | D27: 45978 | E27: 45979 | F27: =E27-D27+1 -> 2 | I27: =H27-G27+1 -> 1 | K27: 대기 | Z27: =J27 | AB27: 데이터 타입 변환 및 포맷 통일(11/17-11/18)
A28: 2.3.3 | B28: 파생 변수 설정(지표설정 등) | C28: DA | D28: 45978 | E28: 45979 | F28: =E28-D28+1 -> 2 | I28: =H28-G28+1 -> 1 | K28: 대기 | Z28: =J28 | AB28: 파생 변수 설정(11/17-11/18)
A29: 2.3.4 | B29: 데이터 스케일링 및 정규화(최종 데이터셋) | C29: DA | D29: 45978 | E29: 45979 | F29: =E29-D29+1 -> 2 | I29: =H29-G29+1 -> 1 | K29: 대기 | Z29: =J29 | AB29: 데이터 스케일링 및 정규화(11/17-11/18)
A30: 3 | B30: 데이터 분석 및 시각화 | D30: 45980 | E30: 45985 | F30: =E30-D30+1 -> 6 | I30: =H30-G30+1 -> 1 | J30: =sum(J31:J44)/COUNT(F31:F44) -> 0 | K30: 대기 | AB30: =J30 -> 0 | AH30: 데이터 분석 및 시각화(11/19-11/24)
A31: 3.1 | B31: 탐색적 데이터 분석(EDA) | D31: 45980 | E31: 45983 | F31: =E31-D31+1 -> 4 | I31: =H31-G31+1 -> 1 | K31: 대기 | AB31: =J31 | AF31: 탐색적 데이터 분석(EDA)(11/19-11/22)
A32: 3.1.1 | B32: 변수별 기초 통계 분석 | C32: TA | D32: 45980 | E32: 45980 | F32: =E32-D32+1 -> 1 | I32: =H32-G32+1 -> 1 | K32: 대기 | AB32: =J32 | AC32: 변수별 기초 통계 분석(11/19-11/19)
A33: 3.1.2 | B33: 주성분 분석 | C33: TA | D33: 45980 | E33: 45981 | F33: =E33-D33+1 -> 2 | I33: =H33-G33+1 -> 1 | K33: 대기 | AB33: =J33 | AD33: 주성분 분석(11/19-11/20)
A34: 3.1.4 | B34: 차트 및 그래프 개발 | C34: TA | D34: 45981 | E34: 45982 | F34: =E34-D34+1 -> 2 | I34: =H34-G34+1 -> 1 | K34: 대기 | AC34: =J34 | AE34: 차트 및 그래프 개발(11/20-11/21)
A35: 3.1.5 | B35: 시각화 분석 결과 해석 | C35: AA, DA, TA | D35: 45981 | E35: 45983 | F35: =E35-D35+1 -> 3 | I35: =H35-G35+1 -> 1 | K35: 대기 | AC35: =J35 | AF35: 시각화 분석 결과 해석(11/20-11/22)
A36: 3.2 | B36: 모델 설계 및 학습 | D36: 45980 | E36: 45985 | F36: =E36-D36+1 -> 6 | I36: =H36-G36+1 -> 1 | K36: 대기 | AB36: =J36 | AH36: 모델 설계 및 학습(11/19-11/24)
A37: 3.2.1 | B37: 모델 후보군 선정 및 알고리즘 검토 | C37: TA | D37: 45980 | E37: 45980 | F37: =E37-D37+1 -> 1 | I37: =H37-G37+1 -> 1 | K37: 대기 | AB37: =J37 | AC37: 모델 후보군 선정 및 알고리즘 검토(11/19-11/19)
A38: 3.2.2 | B38: 모델 입력/출력 변수 정의 | C38: TA | D38: 45980 | E38: 45980 | F38: =E38-D38+1 -> 1 | I38: =H38-G38+1 -> 1 | K38: 대기 | AB38: =J38 | AC38: 모델 입력/출력 변수 정의(11/19-11/19)
A39: 3.2.3 | B39: 학습/검증/테스트 데이터셋 분리 | C39: TA | D39: 45980 | E39: 45980 | F39: =E39-D39+1 -> 1 | I39: =H39-G39+1 -> 1 | K39: 대기 | AB39: =J39 | AC39: 학습/검증/테스트 데이터셋 분리(11/19-11/19)
A40: 3.2.4 | B40: 모델 학습 코드 작성 및 초기 학습 | C40: TA | D40: 45980 | E40: 45981 | F40: =E40-D40+1 -> 2 | I40: =H40-G40+1 -> 1 | K40: 대기 | AB40: =J40 | AD40: 모델 학습 코드 작성 및 초기 학습(11/19-11/20)
...

Sheet 김효정(AA)개인보고
A1: 김효정(AA) 개인 업무 보고
A2: 보고일자 | B2: 퇴근시간 | C2: 금일 업무 상세 | D2: WBS | E2: 상태 | F2: 비고
A3: 45973 | B3: 0.75 | C3: 프로젝트 킥오프 | D3: 1.1 | E3: 완료
C4: 공유 드라이브 구성 및 마일스톤 작성 | D4: 1.1 | E4: 완료

Sheet 김한준(DA)개인보고
A1: 김한준(DA) 개인 업무 보고
A2: 보고일자 | B2: 퇴근시간 | C2: 금일 업무 상세 | D2: WBS | E2: 상태 | F2: 비고
A3: 45973 | B3: 0.75 | C3: 선행연구 및 방법론 탐색 | D3: 1.2.1 | E3: 완료
C4: 문제 정의 및 분석방법 선정 | D4: 1.2.2 | E4: 완료
C5: 데이터 수집 채널 선정 | D5: 1.2.3 | E5: 완료
C6: raw data 수집 | D6: 1.2.4 | E6: 완료

Sheet 이상윤(DA)개인보고
A1: 이상윤(DA) 개인 업무 보고
A2: 보고일자 | B2: 퇴근시간 | C2: 금일 업무 상세 | D2: WBS | E2: 상태 | F2: 비고
A3: 45973 | B3: 0.75 | C3: 선행연구 및 방법론 탐색 | D3: 1.2.1 | E3: 완료
C4: 문제 정의 및 분석방법 선정 | D4: 1.2.2 | E4: 완료
C5: 데이터 수집 채널 선정 | D5: 1.2.3 | E5: 완료

Sheet 정우식(TA)개인보고
A1: 정우식(TA) 개인 업무 보고
A2: 보고일자 | B2: 퇴근시간 | C2: 금일 업무 상세 | D2: WBS | E2: 상태 | F2: 비고
A3: 45972 | B3: 0.75 | C3: 선행연구 및 방법론 탐색 | D3: 1.2.1 | E3: 완료
C4: raw data 수집 | D4: 2.1.1 | E4: 진행중
